<?xml version="1.0"?>

<robot
    xmlns:sensor="http://playerstage.sourceforge.net/gazebo/xmlschema/#sensor"
    xmlns:controller="http://playerstage.sourceforge.net/gazebo/xmlschema/#controller"
    xmlns:interface="http://playerstage.sourceforge.net/gazebo/xmlschema/#interface">
    
    <macro name="smart_arm" params="parent *origin">
        <joint name="arm_base_joint" type="fixed">
            <insert_block name="origin" /> 
            <parent link="${parent}"/>
            <child link="arm_base_link"/>
        </joint>
        
        <link name="arm_base_link">
            <inertial>
                <mass value="0.1" />
                <origin xyz="0.0 0.0 0.0" rpy="0 0 0" />
                <inertia ixx="1.0" ixy="0.0" ixz="0.0"
                         iyy="1.0" iyz="0.0" 
                         izz="1.0" />
            </inertial>
            
            <visual>
                <origin xyz="0.0 0.0 0.0" rpy="0 0 0" />
                <geometry>
                    <mesh filename="package://smart_arm_description/meshes/arm_base.stl"/>
                </geometry>
            </visual>
            
            <collision>
                <origin xyz="0.0 0.0 0.0" rpy="0 0 0" />
                <geometry>
                    <mesh filename="package://smart_arm_description/meshes/arm_base.stl"/>
                </geometry>
            </collision>
        </link>
        
        <!-- Shoulder pan joint and link -->
        <joint name="shoulder_pan_joint" type="revolute" >
            <origin xyz="-0.0075 0 0.025" rpy="0 0 0" />
            <parent link="arm_base_link" />
            <child link="arm_shoulder_pan_link"/>
            
            <axis xyz="0 0 1"/>
            <limit  lower="-1.22"
                    upper="1.22"
                    effort="100"
                    velocity="2.33" />
        </joint>
        
        <transmission type="SimpleTransmission" name="shoulder_pan_trans">
            <actuator name="shoulder_pan_motor" />
            <joint name="shoulder_pan_joint" />
            <mechanicalReduction>1.0</mechanicalReduction>
        </transmission>
        
        <link name="arm_shoulder_pan_link">
            <inertial>
                <mass value="0.3" />
                <origin xyz="0.0 0.0 0.0" rpy="0 0 0" />
                <inertia ixx="1.0" ixy="0.0" ixz="0.0"
                         iyy="1.0" iyz="0.0" 
                         izz="1.0" />
            </inertial>
            
            <visual>
                <origin xyz="0.0 0.0 0.005" rpy="0 0 0" />
                <geometry>
                    <mesh filename="package://smart_arm_description/meshes/arm_shoulder_pan.stl"/>
                </geometry>
            </visual>
            
            <collision>
                <origin xyz="0.0 0.0 0.0" rpy="0 0 0" />
                <geometry>
                    <mesh filename="package://smart_arm_description/meshes/arm_shoulder_pan.stl"/>
                </geometry>
            </collision>
        </link>
        
        <!-- Shoulder tilt joint and link -->
        <joint name="shoulder_tilt_joint" type="revolute">
            <origin xyz="${0.105 - 0.01 - 0.03085/2} 0 ${0.01 + 0.05 - 0.031/2}" rpy="0 0 0" />
            <parent link="arm_shoulder_pan_link"/>
            <child link="arm_shoulder_tilt_link" />
            
            <axis xyz="0 1 0"/>
            <limit  lower="-1.972222"
                    upper="1.04719755"
                    effort="100"
                    velocity="2.33" />
        </joint>
        
        <link name="arm_shoulder_tilt_link">
            <inertial>
                <mass value="0.18" />
                <origin xyz="0.0 0.17 0.0" rpy="0 0 0" />
                <inertia ixx="1.0" ixy="0.0" ixz="0.0"
                         iyy="1.0" iyz="0.0" 
                         izz="1.0" />
            </inertial>
            
            <visual>
                <origin xyz="0.0 0.0 0.0" rpy="0 0 0" />
                <geometry>
                    <mesh filename="package://smart_arm_description/meshes/arm_shoulder_tilt.stl"/>
                </geometry>
            </visual>
            
            <collision>
                <origin xyz="0.0 0.0 0.0" rpy="0 0 0" />
                <geometry>
                    <mesh filename="package://smart_arm_description/meshes/arm_shoulder_tilt.stl"/>
                </geometry>
            </collision>
        </link>
        
        <transmission type="SimpleTransmission" name="shoulder_tilt_trans">
            <actuator name="shoulder_tilt_motor" />
            <joint name="shoulder_tilt_joint" />
            <mechanicalReduction>1.0</mechanicalReduction>
        </transmission>
        
        <!-- Elbow tilt joint and link -->
        <joint name="elbow_tilt_joint" type="revolute">
            <origin xyz="${0.04 - 0.01 + 0.0015 + 0.105 + 0.055 - 0.01} 0 0" rpy="0 0 0" />
            <parent link="arm_shoulder_tilt_link"/>
            <child link="arm_elbow_tilt_link" />
            
            <axis xyz="0 1 0"/>
            <!-- From -113 to 108 degrees -->
            <limit  lower="-1.972222"
                    upper="1.8849556"
                    effort="100"
                    velocity="2.33" />
        </joint>
        
        <link name="arm_elbow_tilt_link">
            <inertial>
                <mass value="0.15" />
                <origin xyz="0.0 0.07 0.0" rpy="0 0 0" />
                <inertia ixx="1.0" ixy="0.0" ixz="0.0"
                         iyy="1.0" iyz="0.0" 
                         izz="1.0" />
            </inertial>
            
            <visual>
                <origin xyz="0.0 0.0 0.0" rpy="0 0 0" />
                <geometry>
                    <mesh filename="package://smart_arm_description/meshes/arm_elbow_tilt.stl"/>
                </geometry>
            </visual>
            
            <collision>
                <origin xyz="0.0 0.0 0.0" rpy="0 0 0" />
                <geometry>
                    <mesh filename="package://smart_arm_description/meshes/arm_elbow_tilt.stl"/>
                </geometry>
            </collision>
        </link>
        
        <transmission type="SimpleTransmission" name="elbow_tilt_trans">
            <actuator name="elbow_tilt_motor" />
            <joint name="elbow_tilt_joint" />
            <mechanicalReduction>1.0</mechanicalReduction>
        </transmission>
        
        <!-- Wrist rotate joint and link -->
        <joint name="wrist_rotate_joint" type="revolute">
            <origin xyz="${0.08 - 0.01} 0 ${0.05 - 0.0115 - 0.0155}" rpy="0 0 0" />
            <parent link="arm_elbow_tilt_link"/>
            <child link="arm_wrist_rotate_link" />
            
            <axis xyz="1 0 0"/>
            <!-- From -150 to 150 degrees -->
            <limit  lower="-2.6179939"
                    upper="2.6179939"
                    effort="100"
                    velocity="2.33" />
        </joint>
        
        <link name="arm_wrist_rotate_link">
            <inertial>
                <mass value="0.12" />
                <origin xyz="0.0 0.05 0.0" rpy="0 0 0" />
                <inertia ixx="1.0" ixy="0.0" ixz="0.0"
                         iyy="1.0" iyz="0.0" 
                         izz="1.0" />
            </inertial>
            
            <visual>
                <origin xyz="0.0 0.0 0.0" rpy="0 0 0" />
                <geometry>
                    <mesh filename="package://smart_arm_description/meshes/arm_wrist_rotate.stl"/>
                </geometry>
            </visual>
            
            <collision>
                <origin xyz="0.0 0.0 0.0" rpy="0 0 0" />
                <geometry>
                    <mesh filename="package://smart_arm_description/meshes/arm_wrist_rotate.stl"/>
                </geometry>
            </collision>
        </link>
        
        <transmission type="SimpleTransmission" name="wrist_rotate_trans">
            <actuator name="wrist_rotate_motor" />
            <joint name="wrist_rotate_joint" />
            <mechanicalReduction>1.0</mechanicalReduction>
        </transmission>
        
        <!-- Gripper right finger joint and link -->
        <joint name="finger_right_joint" type="revolute">
            <origin xyz="${0.0015 + 0.05 - 0.01} ${-0.035/2} 0" rpy="0 0 0" />
            <parent link="arm_wrist_rotate_link"/>
            <child link="arm_right_finger_link" />
            
            <axis xyz="0 0 1"/>
            <!-- From -20 to 20 degrees -->
            <limit  lower="-0.3490658"
                    upper="0.3490658"
                    effort="100"
                    velocity="2.33" />
        </joint>
        
        <link name="arm_right_finger_link">
            <inertial>
                <mass value="0.01" />
                <origin xyz="0.0 0.0 0.0" rpy="0 0 0" />
                <inertia ixx="1.0" ixy="0.0" ixz="0.0"
                         iyy="1.0" iyz="0.0" 
                         izz="1.0" />
            </inertial>
            
            <visual>
                <origin xyz="0.0 0.0 0.0" rpy="0 0 0" />
                <geometry>
                    <mesh filename="package://smart_arm_description/meshes/arm_right_finger.stl"/>
                </geometry>
            </visual>
            
            <collision>
                <origin xyz="0.0 0.0 0.0" rpy="0 0 0" />
                <geometry>
                    <mesh filename="package://smart_arm_description/meshes/arm_right_finger.stl"/>
                </geometry>
            </collision>
        </link>
        
        <transmission type="SimpleTransmission" name="finger_right_trans">
            <actuator name="finger_right_motor" />
            <joint name="finger_right_joint" />
            <mechanicalReduction>1.0</mechanicalReduction>
        </transmission>
        
        <!-- Gripper left finger joint and link -->
        <joint name="finger_left_joint" type="revolute">
            <origin xyz="${0.0015 + 0.05 - 0.01} ${0.035/2} 0" rpy="0 0 0" />
            <parent link="arm_wrist_rotate_link"/>
            <child link="arm_left_finger_link" />
            
            <axis xyz="0 0 1"/>
            <!-- From -20 to 20 degrees -->
            <limit  lower="-0.3490658"
                    upper="0.3490658"
                    effort="100"
                    velocity="2.33" />
        </joint>
        
        <link name="arm_left_finger_link">
            <inertial>
                <mass value="0.01" />
                <origin xyz="0.0 0.0 0.0" rpy="0 0 0" />
                <inertia ixx="1.0" ixy="0.0" ixz="0.0"
                         iyy="1.0" iyz="0.0" 
                         izz="1.0" />
            </inertial>
            
            <visual>
                <origin xyz="0.0 0.0 0.0" rpy="0 0 0" />
                <geometry>
                    <mesh filename="package://smart_arm_description/meshes/arm_left_finger.stl"/>
                </geometry>
            </visual>
            
            <collision>
                <origin xyz="0.0 0.0 0.0" rpy="0 0 0" />
                <geometry>
                    <mesh filename="package://smart_arm_description/meshes/arm_left_finger.stl"/>
                </geometry>
            </collision>
        </link>
        
        <transmission type="SimpleTransmission" name="finger_left_trans">
            <actuator name="finger_left_motor" />
            <joint name="finger_left_joint" />
            <mechanicalReduction>1.0</mechanicalReduction>
        </transmission>
        
        <gazebo reference="arm_base_link">
            <material>SmartArm/GunMetalBrushedAluminum</material>
        </gazebo>
        
        <gazebo reference="arm_shoulder_pan_link">
            <material>SmartArm/GunMetalBrushedAluminum</material>
        </gazebo>
        
        <gazebo reference="arm_shoulder_tilt_link">
            <material>SmartArm/GunMetalBrushedAluminum</material>
        </gazebo>
        
        <gazebo reference="arm_elbow_tilt_link">
            <material>SmartArm/GunMetalBrushedAluminum</material>
        </gazebo>
        
        <gazebo reference="arm_wrist_rotate_link">
            <material>SmartArm/GunMetalBrushedAluminum</material>
        </gazebo>
        
        <gazebo reference="arm_right_finger_link">
            <material>SmartArm/GunMetalBrushedAluminum</material>
        </gazebo>
        
        <gazebo reference="arm_left_finger_link">
            <material>SmartArm/GunMetalBrushedAluminum</material>
        </gazebo>
    </macro>
</robot>
