<?xml version="1.0" ?>
<!-- =================================================================================== -->
<!-- |    This document was autogenerated by xacro from wubble_base.urdf.xacro         | -->
<!-- |    EDITING THIS FILE BY HAND IS NOT RECOMMENDED                                 | -->
<!-- =================================================================================== -->
<robot name="wubble" xmlns:controller="http://playerstage.sourceforge.net/gazebo/xmlschema/#controller" xmlns:interface="http://playerstage.sourceforge.net/gazebo/xmlschema/#interface" xmlns:sensor="http://playerstage.sourceforge.net/gazebo/xmlschema/#sensor">
  <!-- Included URDF Files -->
  <material name="Black">
    <color rgba="0.0 0.0 0.0 1.0"/>
  </material>
  <material name="Blue">
    <color rgba="0.0 0.0 0.8 1.0"/>
  </material>
  <material name="Green">
    <color rgba="0.0 0.8 0.0 1.0"/>
  </material>
  <material name="Grey">
    <color rgba="0.7 0.7 0.7 1.0"/>
  </material>
  <material name="Grey2">
    <color rgba="0.9 0.9 0.9 1.0"/>
  </material>
  <material name="Red">
    <color rgba="0.8 0.0 0.0 1.0"/>
  </material>
  <material name="White">
    <color rgba="1.0 1.0 1.0 1.0"/>
  </material>
  <!-- Properties (Constants) -->
  <!-- VIDERE ERRATIC MOBILE BASE -->
  <link name="base_footprint">
    <inertial>
      <mass value="0.0001"/>
      <origin xyz="0 0 0"/>
      <inertia ixx="0.0001" ixy="0.0" ixz="0.0" iyy="0.0001" iyz="0.0" izz="0.0001"/>
    </inertial>
    <visual>
      <origin rpy="0 0 0" xyz="0 0 0"/>
      <geometry>
        <box size="0.001 0.001 0.001"/>
      </geometry>
      <material name="Green"/>
    </visual>
    <collision>
      <origin rpy="0 0 0" xyz="0 0 0.1285"/>
      <geometry>
        <box size="0.001 0.001 0.001"/>
      </geometry>
    </collision>
  </link>
  <joint name="base_footprint_joint" type="fixed">
    <!-- NB: While you would think this would make it go up, it is oddly reversed.
                 This moves the joint to 0,0,0 where we want it for rviz, etc. -->
    <origin rpy="0 0 0" xyz="0 0 0.1285"/>
    <parent link="base_footprint"/>
    <child link="base_link"/>
  </joint>
  <link name="base_link">
    <inertial>
      <mass value="20"/>
      <origin xyz="-0.1085 0 -0.0775"/>
      <inertia ixx="1.0" ixy="0.0" ixz="0.0" iyy="1.0" iyz="0.0" izz="1.0"/>
    </inertial>
    <visual>
      <origin rpy="0 0 0" xyz="0.0 0.0 0.0"/>
      <geometry>
        <box size="0.217 0.28 0.155"/>
      </geometry>
      <material name="Blue"/>
    </visual>
    <collision>
      <origin rpy="0 0 0" xyz="0.0 0.0 0.0"/>
      <geometry>
        <box size="0.217 0.28 0.155"/>
      </geometry>
    </collision>
  </link>
  <joint name="base_top_joint" type="fixed">
    <origin rpy="0 0 0" xyz="0 0 0.0785"/>
    <!-- 0.051 -->
    <parent link="base_link"/>
    <child link="base_top_link"/>
  </joint>
  <link name="base_top_link">
    <inertial>
      <mass value="1.0"/>
      <origin xyz="-0.00125736 0.0 -0.0032368"/>
      <inertia ixx="0.00995424" ixy="0.0" ixz="0.00000413" iyy="0.01191941" iyz="0.0" izx="0.00000413" izz="0.02181097"/>
    </inertial>
    <visual>
      <origin rpy="0 0 0" xyz="0.0 0.0 0.0"/>
      <geometry>
        <mesh filename="package://erratic_description/meshes/erratic_top.stl"/>
      </geometry>
      <material name="Blue"/>
    </visual>
    <collision>
      <origin rpy="0 0 0" xyz="0.0 0.0 0.0"/>
      <geometry>
        <mesh filename="package://erratic_description/meshes/erratic_top.stl"/>
      </geometry>
    </collision>
  </link>
  <joint name="base_caster_box_joint" type="fixed">
    <origin rpy="0 0 0" xyz="-0.1515 0 0.02275"/>
    <parent link="base_link"/>
    <child link="base_caster_box_link"/>
  </joint>
  <link name="base_caster_box_link">
    <inertial>
      <mass value="0.1"/>
      <origin xyz="0 0 0"/>
      <inertia ixx="0.01" ixy="0.0" ixz="0.0" iyy="0.01" iyz="0.0" izz="0.01"/>
    </inertial>
    <visual>
      <origin rpy="0 0 0" xyz="0.0 0.0 0.0"/>
      <geometry>
        <box size="0.086 0.02 0.1095"/>
      </geometry>
      <material name="Blue"/>
    </visual>
    <collision>
      <origin rpy="0 0 0" xyz="0.0 0.0 0.0"/>
      <geometry>
        <box size="0.086 0.02 0.1095"/>
      </geometry>
    </collision>
  </link>
  <joint name="base_caster_support_joint" type="continuous">
    <origin rpy="0 0 0" xyz="-0.028 0 -0.08625"/>
    <parent link="base_caster_box_link"/>
    <child link="base_caster_support_link"/>
    <axis xyz="0 0 1"/>
    <anchor xyz="0.01 0 0"/>
    <limit effort="100" k_velocity="0" velocity="100"/>
    <joint_properties damping="0.0" friction="0.0"/>
  </joint>
  <transmission name="base_caster_support_trans" type="pr2_mechanism_model/SimpleTransmission">
    <actuator name="base_caster_support_motor"/>
    <joint name="base_caster_support_joint"/>
    <mechanicalReduction>1.0</mechanicalReduction>
  </transmission>
  <link name="base_caster_support_link">
    <inertial>
      <mass value="0.1"/>
      <origin xyz="0 0 0"/>
      <inertia ixx="0.01" ixy="0.0" ixz="0.0" iyy="0.01" iyz="0.0" izz="0.01"/>
    </inertial>
    <visual>
      <origin rpy="0 0 0" xyz="0.0 0.0 0.0"/>
      <geometry>
        <box size="0.03 0.02 0.063"/>
      </geometry>
    </visual>
    <collision>
      <origin rpy="0 0 0" xyz="0.0 0.0 0.0"/>
      <geometry>
        <box size="0.03 0.02 0.063"/>
      </geometry>
    </collision>
  </link>
  <joint name="caster_wheel_joint" type="continuous">
    <origin rpy="0 0 0" xyz="-0.015 0 -0.03"/>
    <parent link="base_caster_support_link"/>
    <child link="caster_wheel_link"/>
    <axis xyz="0 1 0"/>
    <anchor xyz="0 0 0"/>
    <limit effort="100" k_velocity="0" velocity="100"/>
    <joint_properties damping="0.0" friction="0.0"/>
  </joint>
  <transmission name="caster_wheel_trans" type="pr2_mechanism_model/SimpleTransmission">
    <actuator name="caster_wheel_motor"/>
    <joint name="caster_wheel_joint"/>
    <mechanicalReduction>1.0</mechanicalReduction>
  </transmission>
  <link name="caster_wheel_link">
    <inertial>
      <mass value="0.1"/>
      <origin rpy="0 0 0" xyz="0.0 0.0 0.0"/>
      <inertia ixx="0.012411765597" ixy="-0.000711733678" ixz="0.00050272983" iyy="0.015218160428" iyz="-0.000004273467" izz="0.011763977943"/>
    </inertial>
    <visual>
      <origin rpy="1.570795 0 0" xyz="0 0 0"/>
      <geometry>
        <cylinder length="0.01" radius="0.035"/>
      </geometry>
      <material name="Black"/>
    </visual>
    <collision>
      <origin rpy="1.570795 0 0" xyz="0 0 0"/>
      <geometry>
        <cylinder length="0.01" radius="0.035"/>
      </geometry>
    </collision>
  </link>
  <gazebo reference="caster_wheel_link">
    <elem key="mu1" value="50.0"/>
    <elem key="mu2" value="50.0"/>
    <elem key="kp" value="1000000.0"/>
    <elem key="kd" value="1.0"/>
  </gazebo>
  <joint name="computer_mount_joint" type="fixed">
    <origin xyz="-0.08395 -0.0097 0.001"/>
    <parent link="base_top_link"/>
    <child link="computer_link"/>
  </joint>
  <link name="computer_link">
    <inertial>
      <mass value="2"/>
      <origin rpy="0 0 0" xyz="0 0 0.028"/>
      <inertia ixx="0.1" ixy="0" ixz="0" iyy="0.1" iyz="0" izz="0.1"/>
    </inertial>
    <visual>
      <origin rpy="0 0 0" xyz="0 0 0.028"/>
      <geometry>
        <box size="0.17 0.175 0.056"/>
      </geometry>
    </visual>
    <collision>
      <origin rpy="0 0 0" xyz="0 0 0.028"/>
      <geometry>
        <box size="0.17 0.175 0.056"/>
      </geometry>
    </collision>
  </link>
  <gazebo reference="computer_link">
    <material>Erratic/BlueBrushedAluminum</material>
  </gazebo>
  <joint name="base_link_left_motor_joint" type="fixed">
    <origin rpy="0 0 0" xyz="0.075 0.14 -0.0539"/>
    <parent link="base_link"/>
    <child link="base_link_left_motor_link"/>
  </joint>
  <link name="base_link_left_motor_link">
    <inertial>
      <mass value="0.1"/>
      <origin xyz=" 0 0.0125 0 "/>
      <inertia ixx="0.012411765597" ixy="0.0" ixz="0.0" iyy="0.015218160428" iyz="0.0" izz="0.011763977943"/>
    </inertial>
    <visual>
      <origin rpy="1.570795 0 0" xyz="0 0.0125 0"/>
      <geometry>
        <cylinder length="0.025" radius="0.0127"/>
      </geometry>
    </visual>
    <collision>
      <origin rpy="1.570795 0 0" xyz="0 0.0125 0"/>
      <geometry>
        <cylinder length="0.025" radius="0.0127"/>
      </geometry>
    </collision>
  </link>
  <joint name="base_link_left_wheel_joint" type="continuous">
    <origin rpy="0 0 0" xyz="0 0.025 0"/>
    <axis xyz="0 1 0"/>
    <anchor xyz="0 0 0"/>
    <limit effort="100" velocity="100"/>
    <joint_properties damping="0.0" friction="0.0"/>
    <parent link="base_link_left_motor_link"/>
    <child link="base_link_left_wheel_link"/>
  </joint>
  <link name="base_link_left_wheel_link">
    <inertial>
      <mass value="0.1"/>
      <origin xyz=" 0 0 0 "/>
      <inertia ixx="0.012411765597" ixy="0.0" ixz="0.0" iyy="0.015218160428" iyz="0.0" izz="0.011763977943"/>
    </inertial>
    <visual>
      <origin rpy="0 0 1.570795" xyz="0 0 0"/>
      <geometry>
        <mesh filename="package://erratic_description/meshes/erratic_wheel.stl"/>
      </geometry>
      <material name="Black"/>
    </visual>
    <collision>
      <origin rpy="0 0 1.570795" xyz="0 0 0"/>
      <geometry>
        <mesh filename="package://erratic_description/meshes/erratic_wheel.stl"/>
      </geometry>
    </collision>
  </link>
  <gazebo reference="base_link_left_wheel_link">
    <elem key="mu1" value="50.0"/>
    <elem key="mu2" value="50.0"/>
    <elem key="kp" value="100000000.0"/>
    <elem key="kd" value="1.0"/>
    <material>Erratic/Grey</material>
  </gazebo>
  <gazebo reference="base_link_left_motor_link">
    <material>Erratic/White</material>
  </gazebo>
  <transmission name="base_link_left_wheel_trans" type="pr2_mechanism_model/SimpleTransmission">
    <actuator name="base_link_left_wheel_motor"/>
    <joint name="base_link_left_wheel_joint"/>
    <mechanicalReduction>1.0</mechanicalReduction>
  </transmission>
  <joint name="base_link_right_motor_joint" type="fixed">
    <origin rpy="0 0 0" xyz="0.075 -0.14 -0.0539"/>
    <parent link="base_link"/>
    <child link="base_link_right_motor_link"/>
  </joint>
  <link name="base_link_right_motor_link">
    <inertial>
      <mass value="0.1"/>
      <origin xyz=" 0 -0.0125 0 "/>
      <inertia ixx="0.012411765597" ixy="0.0" ixz="0.0" iyy="0.015218160428" iyz="0.0" izz="0.011763977943"/>
    </inertial>
    <visual>
      <origin rpy="1.570795 0 0" xyz="0 -0.0125 0"/>
      <geometry>
        <cylinder length="0.025" radius="0.0127"/>
      </geometry>
    </visual>
    <collision>
      <origin rpy="1.570795 0 0" xyz="0 -0.0125 0"/>
      <geometry>
        <cylinder length="0.025" radius="0.0127"/>
      </geometry>
    </collision>
  </link>
  <joint name="base_link_right_wheel_joint" type="continuous">
    <origin rpy="0 0 0" xyz="0 -0.025 0"/>
    <axis xyz="0 1 0"/>
    <anchor xyz="0 0 0"/>
    <limit effort="100" velocity="100"/>
    <joint_properties damping="0.0" friction="0.0"/>
    <parent link="base_link_right_motor_link"/>
    <child link="base_link_right_wheel_link"/>
  </joint>
  <link name="base_link_right_wheel_link">
    <inertial>
      <mass value="0.1"/>
      <origin xyz=" 0 0 0 "/>
      <inertia ixx="0.012411765597" ixy="0.0" ixz="0.0" iyy="0.015218160428" iyz="0.0" izz="0.011763977943"/>
    </inertial>
    <visual>
      <origin rpy="0 0 1.570795" xyz="0 0 0"/>
      <geometry>
        <mesh filename="package://erratic_description/meshes/erratic_wheel.stl"/>
      </geometry>
      <material name="Black"/>
    </visual>
    <collision>
      <origin rpy="0 0 1.570795" xyz="0 0 0"/>
      <geometry>
        <mesh filename="package://erratic_description/meshes/erratic_wheel.stl"/>
      </geometry>
    </collision>
  </link>
  <gazebo reference="base_link_right_wheel_link">
    <elem key="mu1" value="50.0"/>
    <elem key="mu2" value="50.0"/>
    <elem key="kp" value="100000000.0"/>
    <elem key="kd" value="1.0"/>
    <material>Erratic/Grey</material>
  </gazebo>
  <gazebo reference="base_link_right_motor_link">
    <material>Erratic/White</material>
  </gazebo>
  <transmission name="base_link_right_wheel_trans" type="pr2_mechanism_model/SimpleTransmission">
    <actuator name="base_link_right_wheel_motor"/>
    <joint name="base_link_right_wheel_joint"/>
    <mechanicalReduction>1.0</mechanicalReduction>
  </transmission>
  <gazebo>
    <controller:diffdrive_plugin name="differential_drive_controller" plugin="libdiffdrive_plugin.so">
      <alwaysOn>true</alwaysOn>
      <update>100</update>
      <updateRate>100.0</updateRate>
      <leftJoint>base_link_right_wheel_joint</leftJoint>
      <rightJoint>base_link_left_wheel_joint</rightJoint>
      <wheelSeparation>0.34</wheelSeparation>
      <wheelDiameter>0.1492</wheelDiameter>
      <torque>5</torque>
      <interface:position name="position_iface_0"/>
      <robotNamespace>/</robotNamespace>
      <topicName>cmd_vel</topicName>
    </controller:diffdrive_plugin>
    <controller:gazebo_ros_p3d name="p3d_base_controller" plugin="libgazebo_ros_p3d.so">
      <alwaysOn>true</alwaysOn>
      <updateRate>100.0</updateRate>
      <bodyName>base_link</bodyName>
      <topicName>base_pose_ground_truth</topicName>
      <gaussianNoise>0.01</gaussianNoise>
      <frameName>map</frameName>
      <xyzOffsets>0 0 0</xyzOffsets>
      <rpyOffsets>0 0 0</rpyOffsets>
      <interface:position name="p3d_base_position"/>
    </controller:gazebo_ros_p3d>
    <canonicalBody>base_footprint</canonicalBody>
    <!-- this publishes empty joint_states due to no transmission, but
             triggering robot_state_publisher to publish tf between fixed joints in erratic,
             (e.g. base_laser_link for the base_scan frame) -->
    <controller:gazebo_ros_controller_manager name="gazebo_ros_controller_manager" plugin="libgazebo_ros_controller_manager.so">
      <alwaysOn>true</alwaysOn>
      <updateRate>100.0</updateRate>
      <interface:audio name="gazebo_ros_controller_manager_dummy_iface"/>
    </controller:gazebo_ros_controller_manager>
  </gazebo>
  <gazebo reference="base_link">
    <material>Erratic/BlueBrushedAluminum</material>
  </gazebo>
  <gazebo reference="base_top_link">
    <material>Erratic/BlueBrushedAluminum</material>
  </gazebo>
  <gazebo reference="caster_wheel_link">
    <material>Erratic/Black</material>
  </gazebo>
  <gazebo reference="base_caster_box_link">
    <material>Erratic/Black</material>
  </gazebo>
  <gazebo reference="base_caster_support_link">
    <material>Erratic/White</material>
  </gazebo>
  <!-- HOKUYO LASER ATTACHMENT -->
  <joint name="laser_support_joint" type="fixed">
    <origin rpy="3.14159 0 0" xyz="0.18085 0 -0.001"/>
    <parent link="base_top_link"/>
    <child link="hokuyo_tilt_link"/>
  </joint>
  <link name="hokuyo_tilt_link">
    <inertial>
      <mass value="0.1"/>
      <origin rpy="0 0 0" xyz="0 0 0"/>
      <inertia ixx="0.01" ixy="0" ixz="0" iyy="0.01" iyz="0" izz="0.01"/>
    </inertial>
    <visual>
      <origin rpy="0 0 0" xyz="0 0 0"/>
      <geometry>
        <mesh filename="package://wubble_description/meshes/camera_tilt.stl"/>
      </geometry>
    </visual>
    <collision>
      <origin rpy="0 0 0" xyz="0 0 0"/>
      <geometry>
        <mesh filename="package://wubble_description/meshes/camera_tilt.stl"/>
      </geometry>
    </collision>
  </link>
  <joint name="hokuyo_tilt_joint" type="revolute">
    <origin xyz="-0.019 0 0.043"/>
    <parent link="hokuyo_tilt_link"/>
    <child link="hokuyo_mount_link"/>
    <axis xyz="0 1 0"/>
    <limit effort="100" lower="-0.1" upper="0.785398164" velocity="12.0"/>
    <safety_controller k_position="100" k_velocity="15.0" soft_lower_limit="0.0" soft_upper_limit="0.685398164"/>
    <dynamics damping="50" friction="1"/>
  </joint>
  <transmission name="hokuyo_tilt_trans" type="pr2_mechanism_model/SimpleTransmission">
    <actuator name="hokuyo_tilt_motor"/>
    <joint name="hokuyo_tilt_joint"/>
    <mechanicalReduction>1.0</mechanicalReduction>
  </transmission>
  <link name="hokuyo_mount_link">
    <inertial>
      <mass value="0.01"/>
      <origin rpy="0 0 0" xyz="0 0 0"/>
      <inertia ixx="0.01" ixy="0" ixz="0" iyy="0.01" iyz="0" izz="0.01"/>
    </inertial>
    <visual>
      <origin rpy="0 0 0" xyz="0 0 0"/>
      <geometry>
        <mesh filename="package://wubble_description/meshes/camera_mount.stl"/>
      </geometry>
    </visual>
    <collision>
      <origin rpy="0 0 0" xyz="0 0 0"/>
      <geometry>
        <mesh filename="package://wubble_description/meshes/camera_mount.stl"/>
      </geometry>
    </collision>
  </link>
  <joint name="hokuyo_mount_joint" type="fixed">
    <origin rpy="0 0 0" xyz="0 0 0.023"/>
    <parent link="hokuyo_mount_link"/>
    <child link="hokuyo_link"/>
  </joint>
  <link name="hokuyo_link">
    <inertial>
      <mass value="0.160"/>
      <origin rpy="0 0 0" xyz="0.0 0.0 0.0"/>
      <inertia ixx="1.0" ixy="0.0" ixz="0.0" iyy="1.0" iyz="0.0" izz="1.0"/>
    </inertial>
    <visual>
      <origin rpy="1.570795 0 1.570795" xyz="0.0 0.0 0.0"/>
      <geometry>
        <mesh filename="package://hokuyo_urg_description/meshes/hokuyo_urg.stl"/>
      </geometry>
    </visual>
    <collision>
      <origin rpy="1.570795 0 1.570795" xyz="0.0 0.0 0.0"/>
      <geometry>
        <mesh filename="package://hokuyo_urg_description/meshes/convex/hokuyo_urg_convex.stlb"/>
      </geometry>
    </collision>
  </link>
  <joint name="laser_joint" type="fixed">
    <origin rpy="0 0 0" xyz="0 0 0.06"/>
    <parent link="hokuyo_link"/>
    <child link="laser_link"/>
  </joint>
  <link name="laser_link" type="laser">
    <inertial>
      <mass value="0.001"/>
      <origin rpy="0 0 0" xyz="0 0 0"/>
      <inertia ixx="0.0001" ixy="0" ixz="0" iyy="0.000001" iyz="0" izz="0.0001"/>
    </inertial>
    <visual name="laser_visual">
      <origin rpy="0 0 0" xyz="0 0 0"/>
      <geometry name="laser_visual_geom">
        <box size="0.001 0.001 0.001"/>
      </geometry>
      <material name="Red"/>
    </visual>
    <collision name="laser_collision">
      <origin rpy="0 0 0" xyz="0 0 0"/>
      <geometry name="laser_collision_geom">
        <box size=".001 .001 .001"/>
      </geometry>
    </collision>
  </link>
  <gazebo reference="hokuyo_link">
    <material value="Erratic/Black"/>
  </gazebo>
  <gazebo reference="hokuyo_link">
    <sensor:ray name="laser">
      <rayCount>683</rayCount>
      <rangeCount>683</rangeCount>
      <laserCount>1</laserCount>
      <origin>0.0 0.0 0.0</origin>
      <displayRays>false</displayRays>
      <minAngle>-90</minAngle>
      <maxAngle> 90</maxAngle>
      <minRange>0.06</minRange>
      <maxRange>4.0</maxRange>
      <resRange>0.001</resRange>
      <updateRate>10.0</updateRate>
      <controller:gazebo_ros_laser name="gazebo_ros_laser_controller" plugin="libgazebo_ros_laser.so">
        <gaussianNoise>0.005</gaussianNoise>
        <alwaysOn>true</alwaysOn>
        <updateRate>10.0</updateRate>
        <topicName>tilt_laser/scan</topicName>
        <deprecatedTopicName>tilt_scan</deprecatedTopicName>
        <frameName>laser_link</frameName>
        <interface:laser name="gazebo_ros_laser_iface"/>
      </controller:gazebo_ros_laser>
    </sensor:ray>
  </gazebo>
  <!-- GAZEBO MATERIALS -->
  <gazebo reference="hokuyo_tilt_link">
    <material>Erratic/Black</material>
  </gazebo>
  <gazebo reference="hokuyo_mount_link">
    <material>SmartArm/GunMetalBrushedAluminum</material>
  </gazebo>
</robot>

